Workbook

Sheet Soft Launch Budget
A1: Chokro — Soft Launch Budget | B1: 400 | C1: ← expert budget, USD
A2: Soft launch 30 September 2026 · every figure below was supplied by Arnish in chat, 2 September 2026 · all amounts BDT unless marked
A4: Item | B4: Period | C4: Low (BDT) | D4: High (BDT) | E4: As supplied
A5: CATEGORY 1 — BUSINESS REGISTRATION
A6: DNCC Trade License Fee (Category 253) | B6: Annual | C6: 2000 | D6: 2000 | E6: Annual license fee
A7: Signboard Tax | B7: Annual | C7: 480 | D7: 480 | E7: If applicable
A8: VAT on fees | B8: Annual | C8: 372 | D8: 372 | E8: Government VAT component
A9: Tax / Source Tax | B9: Annual | C9: 3000 | D9: 3000 | E9: Depends on applicable rules
A10: License Book / Form / Processing | B10: One-time | C10: 270 | D10: 500 | E10: Approximate — supplied as a range
A11: Documentation & photocopy | B11: One-time | C11: 200 | D11: 500 | E11: Practical expense — supplied as a range
A12: Subtotal — registration | C12: =SUM(C6:C11) -> 6322 | D12: =SUM(D6:D11) -> 6852
A14: Item | B14: Period | C14: Low (BDT) | D14: High (BDT) | E14: As supplied
A15: CATEGORY 2 — TECHNOLOGY
A16: Google Play developer account | B16: One-time | C16: 3080 | D16: 3080 | E16: $25 one-time
A17: Apple Developer Program | B17: Annual | C17: 12198 | D17: 12198 | E17: $99 per year
A18: .com domain | B18: Annual | C18: 1199 | D18: 1199 | E18: Per year
A19: .com.bd domain | B19: Annual | C19: 2500 | D19: 2500 | E19: Per year
A20: Image hosting — Cloudinary plan | B20: Monthly | C20: 12198 | D20: 12198 | E20: Storage + bandwidth + derivations
A21: AI screening — Groq vision | B21: Monthly | C21: 1525 | D21: 1525 | E21: One call per disposal and per claim
A22: App server — Node service | B22: Monthly | C22: 3080 | D22: 3080 | E22: Always-on instance(s)
A23: Error monitoring — Sentry Team | B23: Monthly | C23: 3190.73 | D23: 3190.73 | E23: Team tier
A24: Subtotal — technology (as listed, mixed periods) | C24: =SUM(C16:C23) -> 38970.73 | D24: =SUM(D16:D23) -> 38970.73
A25: This subtotal is NOT spendable as one figure — it adds a one-time fee, four annual fees and four monthly charges. The roll-up below separates them.
A27: Item | B27: Period | C27: Low (BDT) | D27: High (BDT) | E27: As supplied
A28: CATEGORY 3 — HIRED EXPERTISE
A29: Manual Review Operator | B29: One-time | E29: Part of the $400
A30: UI/UX | B30: One-time | E30: Part of the $400
A31: QA Engineer — including verifying that unauthenticated script access actually fails | B31: One-time | E31: Part of the $400
A32: Security Assurance | B32: One-time | E32: Part of the $400
A33: Total paid to hired experts | B33: One-time | C33: =$B$1*Basis!$B$6 -> 49284 | D33: =$B$1*Basis!$B$6 -> 49284 | E33: $400 in total across all four roles above
A34: Subtotal — hired expertise | C34: =C33 -> 49284 | D34: =D33 -> 49284
A36: Item | B36: Period | C36: Low (BDT) | D36: High (BDT) | E36: As supplied
A37: ROLL-UP BY PERIOD
A38: One-time total | C38: =C10+C11+C16+C33 -> 52834 | D38: =D10+D11+D16+D33 -> 53364 | E38: Play account, licence book/form, documentation, and the whole expert budget.
A39: Annual total — per year | C39: =C6+C7+C8+C9+C17+C18+C19 -> 21749 | D39: =D6+D7+D8+D9+D17+D18+D19 -> 21749 | E39: Trade licence, signboard tax, VAT, source tax, Apple Developer, both domains. These renew.
A40: Monthly total — per month | C40: =SUM(C20:C23) -> 19993.73 | D40: =SUM(D20:D23) -> 19993.73 | E40: Cloudinary, Groq screening, app server, Sentry. These recur every month.
A41: SOFT LAUNCH BUDGET — one-time + first year's annual fees + 1 month of running cost | C41: =C38+C39+C40 -> 94576.73 | D41: =D38+D39+D40 -> 95106.73 | E41: What it costs to get to 30 September 2026 and run the first month.
A42: same figure in USD | C42: =C41/Basis!$B$6 -> 767.60596 | D42: =D41/Basis!$B$6 -> 771.90756
A44: First twelve months | C44: =C38+C39+C40*12 -> 314507.76 | D44: =D38+D39+D40*12 -> 315037.76 | E44: One-time plus one year of annual fees plus twelve months of running cost.
A45: same figure in USD | C45: =C44/Basis!$B$6 -> 2552.6155 | D45: =D44/Basis!$B$6 -> 2556.9171
...

Sheet Basis
A1: Basis
A2: Where every figure came from, and the one classification decision made on top of them.
A4: Exchange rate
A5: Driver | B5: Value | D5: Basis
A6: USD / BDT | B6: 123.21 | D6: Not an outside figure — it is implied by Arnish's own numbers. Google Play $25 → ৳3,080 and Apple Developer $99 → ৳12,198 both give 123.2. Used only to convert the $400 expert budget into taka and to show USD equivalents.
A8: The one thing added on top of the supplied data
A9: Period classification | D9: The figures were supplied in one list without periods. They have been sorted into ONE-TIME, ANNUAL and MONTHLY, because adding them as a flat list gives ৳38,971 for technology when the true first-year technology cost is about eight times that. No amount was changed. Cloudinary, Groq, the app server and Sentry are all monthly vendor charges; the trade licence, signboard tax and both domains renew annually.
A11: Every figure, as supplied
A12: Figure | B12: As supplied | C12: Period used | D12: Note
A13: DNCC Trade License Fee (Category 253) | B13: ৳2,000 | C13: Annual | D13: Arnish's own note: "Annual license fee".
A14: Signboard Tax | B14: ৳480 | C14: Annual | D14: Arnish's own note: "If applicable". Renews with the licence.
A15: VAT on fees | B15: ৳372 | C15: Annual | D15: Arnish's own note: "Government VAT component". Equals 15% of ৳2,000 + ৳480 exactly.
A16: Tax / Source Tax | B16: ৳3,000 | C16: Annual | D16: Arnish's own note: "Depends on applicable rules". Treated as annual — confirm at the ward office.
A17: License Book / Form / Processing | B17: ৳270–500 | C17: One-time | D17: Supplied as a range, kept as a range.
A18: Documentation & photocopy | B18: ৳200–500 | C18: One-time | D18: Supplied as a range, kept as a range.
A19: Google Play developer account | B19: ৳3,080 | C19: One-time | D19: $25, paid once per account.
A20: Apple Developer Program | B20: ৳12,198 | C20: Annual | D20: $99, renews every year.
A21: .com domain | B21: ৳1,199 | C21: Annual | D21: Registrar renewal.
A22: .com.bd domain | B22: ৳2,500 | C22: Annual | D22: BTCL renewal.
A23: Image hosting — Cloudinary plan | B23: ৳12,198 | C23: Monthly | D23: Arnish's own note: "Storage + bandwidth + derivations". Subscription tier, billed monthly.
... A27: Manual Review Operator · UI/UX · QA Engineer · Security Assurance | B27: $400 total | C27: One-time | D27: Arnish: "I am going to hiring some expart to work on it and paying them 400 USD in total". One combined figure for all four roles, not $400 each.
A29: One arithmetic correction
B30: Stated | C30: Computed | D30: Note
A31: Registration total | B31: ৳6,500–7,000 | C31: ৳6,322–6,852 | D31: The six supplied registration rows sum to ৳6,322 at the low end and ৳6,852 at the high end. Arnish's stated estimate was about ৳180 high at the bottom of the range and ৳150 high at the top. The computed figure is used throughout.
A33: Scope — what this plan does NOT include
A34: Because it uses only the figures supplied in chat, this plan carries no line for: a Mac or any hardware (required to build and submit an iOS app); Firebase / Blaze; Redis; a trademark filing; bank account opening; founder or staff salaries beyond the $400; the manual review operator as an ongoing monthly cost once volume grows; marketing; office or rent; or any contingency. Those are real costs and several are unavoidable — they are simply outside the data set this plan was asked to cover.
